Workbook
Name ACTION: #REF!
Name ACTION: #REF!
Name ACTION: #REF!

Sheet Test case List
D1: TEST CASE LIST
B3: Project Name | D3: =[2]Cover!C4 -> Xây dựng hệ thống quản lý kho hàng và bán lẻ cho cửa hàng điện thoại
B4: Project Code | D4: =[2]Cover!C5 -> KH52
B5: Test Environment Setup Description | D5: 1. Apache Tomcat 9 2. Eclipse 3. MySQL 4. Web Browser
B8: No | C8: Function Name | D8: Sheet Name | E8: Description | F8: Pre-Condition | G8: Column1
B9: =ROW(C9)-8 -> 1 | C9: Function - Đăng nhập | D9: Quản lý tài khoản | E9: Check GUI và FUNC chức năng đăng nhập | F9: Tại Trang chủ: Click [Đăng nhập].
B10: =ROW(C10)-8 -> 2 | C10: Function - Đăng kí | D10: Quản lý tài khoản | E10: Check GUI và FUNC đăng kí | F10: Tại Trang chủ: Click [Đăng kí].
B11: =ROW(C11)-8 -> 3 | C11: Function - Thông tin cá nhân | D11: Quản lý tài khoản | E11: Check GUI và FUNC chức năng xem thông tin cá nhân | F11: Tại Trang chủ: Click [Quản lý tài khoản cá nhân].
B12: =ROW(C12)-8 -> 4 | C12: Functon - Sửa thông tin cá nhân | D12: Quản lý tài khoản | E12: Check GUI và FUNC chức năng sửa thông tin cá nhân | F12: Tại màn hình Quản lý tài khoản cá nhân: Click [Sửa thông tin cá nhân].
B13: =ROW(C13)-8 -> 5 | C13: Functon - Sửa mật khẩu | D13: Quản lý tài khoản | E13: Check GUI và FUNC chức năng sửa mật khẩu | F13: Tại màn hình Quản lý tài khoản cá nhân: Click [Sửa mật khẩu].
B14: =ROW(C14)-8 -> 6 | C14: Layout QL Tài khoản | D14: Layout QL Tài khoản | E14: GUI chức năng Quản lý tài khoản
B15: =ROW(C15)-8 -> 7 | C15: Function - Danh sách khách hàng | D15: Quản lý khách hàng - Admin | E15: Check GUI và FUNC chức năng Danh sách khách hàng | F15: Tại menu Quản lý khách hàng: Click [Danh sách khách hàng].
B16: =ROW(C16)-8 -> 8 | C16: Function - Lịch sử mua hàng khách hàng | D16: Quản lý khách hàng - Admin | E16: Check GUI và FUNC chức năng Lịch sử mua hàng khách hàng | F16: Tại Danh sách khách hàng: Click [Lịch sử mua hàng]
B17: =ROW(C17)-8 -> 9 | C17: Function - Phân loại & CSKH | D17: Quản lý khách hàng - Admin | E17: Check GUI và FUNC chức năng Phân loại & CSKH | F17: Tại Danh sách khách hàng: Click [Phân loại & CSKH]
B18: =ROW(C18)-8 -> 10 | C18: Layout Quản lý khách hàng | D18: Layout Quản lý khách hàng - Admin | E18: GUI chức năng Quản lý khách hàng
B19: =ROW(C19)-8 -> 11 | C19: Function - Trang chủ | D19: Đặt hàng & quản lý đơn hàng | E19: Check GUI và FUNC chức năng Trang chủ | F19: Sau khi đăng nhập Hiện màn hình Trang chủ
B20: =ROW(C20)-8 -> 12 | C20: Function - Chi tiết sản phẩm | D20: Đặt hàng & quản lý đơn hàng | E20: Check GUI và FUNC chức năng Chi tiết sản phẩm | F20: Tại Trang chủ Click [Xem chi tiết sản phẩm]
B21: =ROW(C21)-8 -> 13 | C21: Function - Giỏ hàng | D21: Đặt hàng & quản lý đơn hàng | E21: Check GUI và FUNC chức năng Giỏ hàng | F21: Tại Trang chủ Click [Giỏ hàng]
B22: =ROW(C22)-8 -> 14 | C22: Function - Đặt hàng | D22: Đặt hàng & quản lý đơn hàng | E22: Check GUI và FUNC chức năng Đặt hàng | F22: Tại Trang chủ Click [Đặt hàng]
B23: =ROW(C23)-8 -> 15 | C23: Function - Danh sách đơn hàng | D23: Đặt hàng & quản lý đơn hàng | E23: Check GUI và FUNC chức năng Danh sách đơn hàng | F23: Tại Trang chủ Click [Danh sách đơn]
B24: =ROW(C24)-8 -> 16 | C24: Function - Xem chi tiết đơn hàng | D24: Đặt hàng & quản lý đơn hàng | E24: Check GUI và FUNC chức năng Xem chi tiết đơn hàng | F24: Tại Xem chi tiết Click [Danh sách đơn hàng]
B25: =ROW(C25)-8 -> 17 | C25: Function - Hủy đơn hàng | D25: Đặt hàng & quản lý đơn hàng | E25: Check GUI và FUNC chức năng Hủy đơn hàng | F25: Tại Danh sách đơn Click [Hủy]
B26: =ROW(C26)-8 -> 18 | C26: Layout Đặt hàng & QL đơn hàng | D26: Layout Đặt hàng & QL đơn hàng | E26: GUI chức năng Quản lý đơn hàng
B27: =ROW(C27)-8 -> 19 | C27: Function - Theo dõi chi phí | D27: Quản lý chi phí vận hành | E27: Check GUI và FUNC chức năng Theo dõi chi phí | F27: Tại menu “Quản lý chi phí vận hành” Click [Theo dõi chi phí]
B28: =ROW(C28)-8 -> 20 | C28: Function - Xem chi tiết chi phí | D28: Quản lý chi phí vận hành | E28: Check GUI và FUNC chức năng Xem chi tiết đơn hàng | F28: Tại Tại menu “Quản lý chi phí vận hành” Click [Xem chi tiết ]
B29: =ROW(C29)-8 -> 21 | C29: Function - Xem lịch sử chỉnh sửa chi phí | D29: Quản lý chi phí vận hành | E29: Check GUI và FUNC chức năng Xem lịch sử chỉnh sửa chi phí | F29: Tại Tại menu “Quản lý chi phí vận hành” Click [Xem lịch sử ]
B30: =ROW(C30)-8 -> 22 | C30: Function - Lọc chi phí nhập hàng | D30: Quản lý chi phí vận hành | E30: Check GUI và FUNC chức năng Lọc chi phí nhập hàng | F30: Tại Tại menu “Quản lý chi phí vận hành” Click [Nhập hàng ]
B31: =ROW(C31)-8 -> 23 | C31: Function -Lọc chi phí bảo trì | D31: Quản lý chi phí vận hành | E31: Check GUI và FUNC chức năng Lọc chi phí bảo trì | F31: Tại Tại menu “Quản lý chi phí vận hành” Click [Bảo trì ]
B32: =ROW(C32)-8 -> 24 | C32: Function - Lọc chi phí vận chuyển | D32: Quản lý chi phí vận hành | E32: Check GUI và FUNC chức năng Lọc chi phí vận chuyển | F32: Tại Tại menu “Quản lý chi phí vận hành” Click [Vận chuyển ]
B33: =ROW(C33)-8 -> 25 | C33: Layout Quản lý chi phí vận hành | D33: Layout QL Chi phí vận hành | E33: GUI chức năng Quản lý chi phí vận hành
B34: =ROW(C34)-8 -> 26 | C34: Function - Xem chi tiết sản phẩm | D34: Tìm kiếm sản phẩm | E34: Check GUI và FUNC chức năng Xem chi tiết sản phẩm | F34: Tại Trang chủ: Click [Tìm kiếm sản phẩm].
B35: =ROW(C35)-8 -> 27 | C35: Layout Tìm kiếm sản phẩm | D35: Layout Tìm kiếm sản phẩm | E35: GUI chức năng Tìm kiếm sản phẩm

Sheet QLChiPhiVanHanh
A2: Module Code | B2: Quản lý chi phí vận hành
A3: Test requirement | B3: 1. Theo dõi chi phí 2. Xem chi tiết chi phí 3. Xem lịch sử chỉnh sửa chi phí 4. Lọc chi phí nhập hàng 5. Lọc chi phí bảo trì 6. Lọc chi phí vận chuyển
A4: Tester | B4: Hồ Bảo Toàn
A5: Pass | B5: Fail | C5: Untested | D5: N/A | E5: Number of Test cases
A6: =COUNTIF(F11:F990,"Pass") -> 0 | B6: =COUNTIF(F11:F990,"Fail") -> 0 | C6: =E6-D6-B6-A6 -> 58 | D6: =COUNTIF(F$11:F$990,"N/A") -> 0 | E6: =COUNTA(A11:A990) -> 58
A8: ID | B8: Test Case Description | C8: Test Case Procedure | D8: Expected Output | E8: Inter-test case Dependence | F8: Result | G8: Test date | H8: Note
B9: Function : Theo dõi chi phí
B10: Check FUNC-Theo dõi chi phí
A11: FUNC-CostTrack-01 | B11: Hiển thị danh sách chi phí vận hành | C11: Truy cập màn hình theo dõi chi phí vận hành | D11: Danh sách chi phí hiển thị đầy đủ đúng logic
A12: FUNC-CostTrack-02 | B12: Xem lịch sử khoản chi phí | C12: Nhấn nút "Xem lịch sử" ở khoản chi phí bất kỳ | D12: Chuyển sang màn hình/ popup lịch sử liên quan
A13: FUNC-CostTrack-03 | B13: Xem chi tiết khoản chi phí | C13: Nhấn nút "Xem chi tiết" ở khoản chi phí bất kỳ | D13: Hiện thông tin chi tiết khoản chi phí
A14: FUNC-CostTrack-04 | B14: Quay lại | C14: Nhấn nút "Quay lại" | D14: Chuyển về màn hình trước
B15: Check GUI-Theo dõi chi phí
A16: GUI-CostTrack-01 | B16: [Quay lại] Button | C16: Nhấn nút Quay lại | D16: Status = enable
A17: GUI-CostTrack-02 | B17: [Loại chi phí] Label | C17: Hiển thị đúng loại chi phí từng dòng | D17: Status = disable
A18: GUI-CostTrack-03 | B18: [Số tiền] Label | C18: Hiển thị đúng số tiền từng dòng | D18: Status = disable
A19: GUI-CostTrack-04 | B19: [Ngày phát sinh] Label | C19: Hiển thị ngày phát sinh cho từng chi phí | D19: Status = disable
A20: GUI-CostTrack-05 | B20: [Ghi chú] Label | C20: Hiển thị ghi chú đúng cho các khoản chi phí | D20: Status = disable
A21: GUI-CostTrack-06 | B21: [Xem lịch sử] Button | C21: Nhấn để xem lịch sử khoản chi phí | D21: Status = enable
A22: GUI-CostTrack-07 | B22: [Xem chi tiết] Button | C22: Nhấn để xem chi tiết khoản chi phí | D22: Status = enable
B23: Function : Xem chi tiết chi phí
B24: Check FUNC-Xem chi tiết chi phí
A25: FUNC-CostDetail-01 | B25: Hiển thị chi tiết chi phí | C25: Vào màn hình chi tiết chi phí | D25: Đúng loại, số tiền, ngày phát sinh
A26: FUNC-CostDetail-02 | B26: Hiển thị bảng lịch sử chỉnh sửa | C26: Kiểm tra dữ liệu lịch sử sửa (ngày, người sửa) | D26: Hiển thị bảng đầy đủ đúng logic
A27: FUNC-CostDetail-03 | B27: Đóng màn hình | C27: Nhấn nút "Đóng" | D27: Đóng popup/màn hình chi tiết chi phí
B28: Check GUI-Xem chi tiết chi phí
A29: GUI-CostDetail-01 | B29: [Loại chi phí] Label | C29: Hiển thị đúng loại chi phí | D29: Status = disable
A30: GUI-CostDetail-02 | B30: [Số tiền] Label | C30: Hiển thị đúng số tiền | D30: Status = disable
A31: GUI-CostDetail-03 | B31: [Ngày phát sinh] Label | C31: Hiển thị ngày phát sinh hợp lệ | D31: Status = disable
A32: GUI-CostDetail-04 | B32: [Bảng lịch sử chỉnh sửa] Table | C32: Hiển thị lịch sử sửa đổi (ngày sửa, người sửa) | D32: Status = disable
A33: GUI-CostDetail-05 | B33: [Đóng] Button | C33: Nhấn nút Đóng | D33: Status = enable
B34: Function : Xem lịch sử chỉnh sửa chi phí
B35: Check FUNC-Xem lịch sử chỉnh sửa chi phí
A36: FUNC-CostHistory-01 | B36: Hiển thị bảng lịch sử chỉnh sửa | C36: Truy cập màn hình xem lịch sử của khoản chi phí | D36: Hiển thị đủ thời gian, nội dung, người thực hiện
A37: FUNC-CostHistory-02 | B37: Đóng màn hình lịch sử | C37: Nhấn nút "Đóng" | D37: Đóng popup/màn lịch sử đúng logic
B38: Check GUI-Xem lịch sử chỉnh sửa chi phí
A39: GUI-CostHistory-01 | B39: [Bảng lịch sử chỉnh sửa] Table | C39: Hiển thị lịch sử sửa đổi chi phí (thời gian, nội dung, người thực hiện) | D39: Status = disable
A40: GUI-CostHistory-02 | B40: [Thời gian chỉnh sửa] Label | C40: Hiển thị đúng thời gian chỉnh sửa | D40: Status = disable
A41: GUI-CostHistory-03 | B41: [Nội dung thay đổi] Label | C41: Hiển thị đầy đủ nội dung thay đổi | D41: Status = disable
A42: GUI-CostHistory-04 | B42: [Người thực hiện] Label | C42: Hiển thị đúng tên người thực hiện | D42: Status = disable
...

Sheet Layout QL Chi phí vận hành

Sheet Tìm kiếm sản phẩm
A2: Module Code | B2: Tìm kiếm sản phẩm
A3: Test requirement | B3: 1. Xem chi tiết sản phẩm
A4: Tester | B4: Hồ Bảo Toàn
A5: Pass | B5: Fail | C5: Untested | D5: N/A | E5: Number of Test cases
A6: =COUNTIF(F11:F1027,"Pass") -> 0 | B6: =COUNTIF(F11:F1027,"Fail") -> 0 | C6: =E6-D6-B6-A6 -> 14 | D6: =COUNTIF(F$11:F$1027,"N/A") -> 0 | E6: =COUNTA(A11:A1027) -> 14
A8: ID | B8: Test Case Description | C8: Test Case Procedure | D8: Expected Output | E8: Inter-test case Dependence | F8: Result | G8: Test date | H8: Note
B9: Function : Xem chi tiết sản phẩm
B10: Check FUNC-Xem chi tiết sản phẩm
A11: FUNC-CTSP-01 | B11: Hiển thị dữ liệu | C11: 1. Từ màn hình "Tìm kiếm sản phẩm", click vào 1 link "Mã sản phẩm" bất kỳ (e.g., SP01 - Iphone 17 Promax). | D11: Chuyển sang màn hình Xem chi tiết sản phẩm
C12: 2. Quan sát màn hình "Xem chi tiết sản phẩm". | D12: Tất cả thông tin được hiển thị chính xác
A13: FUNC-CTSP-02 | B13: Chức năng [Quay lại] | C13: 1. Đang ở màn hình "Xem chi tiết sản phẩm". 2. Nhấn nút [Quay lại]. | D13: Hệ thống quay trở lại màn hình trước đó (là màn hình "Tìm kiếm sản phẩm" với danh sách vừa tìm).
A14: FUNC-CTSP-03 | B14: Chức năng Tab [Tìm kiếm sản phẩm] | C14: 1. Đang ở màn hình "Xem chi tiết sản phẩm". 2. Nhấn vào tab [Tìm kiếm sản phẩm] ở menu bên trái. | D14: Chuyển tới màn hình "Tìm kiếm sản phẩm".
B18: Check GUI-Xem chi tiết sản phẩm
A19: GUI-View-01 | B19: [Tên sản phẩm] Textbox | C19: Hiển thị tên sản phẩm hợp lệ | D19: Status = disable Default = Lấy dữ liệu từ cột Tên sản phẩm trong bảng Sản phẩm Max-length = 100
A20: GUI-View-02 | B20: [Mã sản phẩm] Textbox | C20: Hiển thị mã sản phẩm hợp lệ | D20: Status = disable Default = Lấy dữ liệu từ cột Mã sản phẩm trong bảng Sản phẩm Max-length = 50
A21: GUI-View-03 | B21: [Hãng sản xuất] Textbox | C21: Hiển thị hãng sản xuất hợp lệ | D21: Status = disable Default = Lấy dữ liệu từ cột Hãng sản suất trong bảng Sản phẩm Max-length = 50
A22: GUI-View-04 | B22: [Loại sản xuất] Textbox | C22: Hiển thị loại sản xuất hợp lệ | D22: Status = disable Default = Lấy dữ liệu từ cột Tên danh mục trong bảng Danh mục Max-length = 50
A23: GUI-View-05 | B23: [Giá bán] Textbox | C23: Hiển thị giá bán hợp lệ | D23: Default = Lấy dữ liệu từ cột Giá bán trong bảng Sản phẩm Max-length = 20
A24: GUI-View-06 | B24: [Số lượng tồn kho] Textbox | C24: Hiển thị số lượng tồn kho hợp lệ | D24: Status = disable Default = Lấy dữ liệu từ cột Số lượng tồn kho trong bảng Sản phẩm Max-length = 5
A25: GUI-View-07 | B25: [Tình trạng] Textbox | C25: Hiển thị tình trạng sản phẩm hợp lệ | D25: Status = disable Default = Lấy dữ liệu từ cột Tình trạng trong bảng Sản phẩm Max-length = 15
A26: GUI-View-08 | B26: [Chính sách bảo hành] Textbox | C26: Hiển thị chính sách bảo hành hợp lệ | D26: Status = disable Default = Lấy dữ liệu từ cột Chính sách bảo hành trong bảng Sản phẩm Max-length = 255
A27: GUI-View-09 | B27: [Đánh giá sản phẩm] Star-Rating | C27: Hiển thị số sao hợp lệ | D27: Status = disable Default = Lấy dữ liệu từ cột Đánh giá sản phẩm trong bản Sản phẩm Max-length = 5
A28: GUI-View-10 | B28: [Bình luận khách hàng] Textbox | C28: Hiển thị bình luận khách hàng hợp lệ | D28: Status = disable Default = Lấy dữ liệu từ cột Nội dung trong bảng Phản hồi Max-length = 255
A29: GUI-View-11 | B29: [Quay lại] Button | C29: Nhấn nút Quay lại | D29: Status = enable

Sheet Layout Tìm kiếm sản phẩm

Sheet Đặt hàng & quản lý đơn hàng
A2: Module Code | B2: Đặt hàng & quản lý đơn hàng
A3: Test requirement | B3: 1. Trang chủ 2. Chi tiết sản phẩm 3. Giỏ hàng 4. Đặt hàng 5. Danh sách đơn 6. Xem chi tiết đơn hàng 7. Hủy đơn hàng
A4: Tester | B4: Hồ Bảo Toàn
A5: Pass | B5: Fail | C5: Untested | D5: N/A | E5: Number of Test cases
A6: =COUNTIF(F11:F1023,"Pass") -> 0 | B6: =COUNTIF(F11:F1023,"Fail") -> 0 | C6: =E6-D6-B6-A6 -> 85 | D6: =COUNTIF(F$11:F$1023,"N/A") -> 0 | E6: =COUNTA(A11:A1023) -> 85
A8: ID | B8: Test Case Description | C8: Test Case Procedure | D8: Expected Output | E8: Inter-test case Dependence | F8: Result | G8: Test date | H8: Note
B9: Function : Trang chủ
B10: Check FUNC-Trang chủ
A11: FUNC-Home-01 | B11: Tìm kiếm sản phẩm | C11: Nhập từ khoá và bấm Enter/icon search | D11: Hiển thị đúng danh sách sản phẩm lọc theo từ khoá
A12: FUNC-Home-02 | B12: Hiển thị danh sách sản phẩm trang đầu | C12: Vào trang chủ | D12: Hiển thị danh sách sản phẩm mặc định
A13: FUNC-Home-03 | B13: Xem chi tiết sản phẩm | C13: Nhấn link "Xem chi tiết" của sản phẩm | D13: Chuyển sang màn hình xem chi tiết sản phẩm
A14: FUNC-Home-04 | B14: Thêm vào giỏ hàng | C14: Nhấn nút "Thêm vào giỏ hàng" sản phẩm bất kỳ | D14: Sản phẩm vào giỏ, số lượng trên giỏ tăng lên hoặc báo thành công
A15: FUNC-Home-05 | B15: Chuyển trang phân trang | C15: Nhấn <<, <, số trang, >, >> | D15: Danh sách sản phẩm cập nhật đúng trang
A16: FUNC-Home-06 | B16: Vào danh sách đơn | C16: Nhấn nút "Danh sách đơn" | D16: Mở/truy cập màn hình danh sách đơn hàng
A17: FUNC-Home-07 | B17: Vào giỏ hàng | C17: Nhấn nút "Giỏ hàng" | D17: Chuyển màn hình sang giao diện giỏ hàng
B21: Check GUI-Trang chủ
A22: GUI-Home-01 | B22: [Search] Textbox | C22: Nhập từ khoá tìm kiếm | D22: Status = enable Max-length = 100
A23: GUI-Home-02 | B23: [Danh sách đơn] Button | C23: Nhấn nút Danh sách đơn | D23: Status = enable
A24: GUI-Home-03 | B24: [Giỏ hàng] Button | C24: Nhấn nút Giỏ hàng | D24: Status = enable
A25: GUI-Home-04 | B25: [Ảnh sản phẩm] Image | C25: Hiển thị ảnh sản phẩm | D25: Status = enable Default = Lấy dữ liệu từ cột Ảnh trong bảng Sản phẩm
A26: GUI-Home-05 | B26: [Tên/giá/màu sản phẩm] Label | C26: Hiển thị tên, giá, màu sản phẩm | D26: Status = disable
A27: GUI-Home-06 | B27: [Xem chi tiết] Link | C27: Nhấn vào link "Xem chi tiết" | D27: Status = enable
A28: GUI-Home-07 | B28: [Thêm vào giỏ hàng] Button | C28: Nhấn nút Thêm vào giỏ hàng | D28: Status = enable
A29: GUI-Home-08 | B29: [Phân trang] Button | C29: Nhấn các nút <<, <, số trang, >, >> | D29: Status = enable
B30: Function : Chi tiết sản phẩm
B31: Check FUNC-Chi tiết sản phẩm
A32: FUNC-Detait-01 | B32: Hiển thị thông tin chi tiết sản phẩm | C32: Người dùng vào/truy cập trang chi tiết sản phẩm | D32: Hiển thị đúng thông tin các trường trên form
A33: FUNC-Detait-02 | B33: Hiển thị ảnh sản phẩm | C33: Có dữ liệu ảnh đại diện sản phẩm | D33: Hiển thị đúng ảnh đại diện
A34: FUNC-Detait-03 | B34: Quay lại | C34: Nhấn nút Quay lại | D34: Quay lại trang trước đúng logic
B35: Check GUI-Chi tiết sản phẩm
A36: GUI-Detail-01 | B36: [Tên sản phẩm] Textbox | C36: Hiển thị tên sản phẩm | D36: Status = enable Default = Lấy dữ liệu từ cột Tên sản phẩm trong bảng Sản phẩm Max-length = 100
A37: GUI-Detail-02 | B37: [Mã sản phẩm] Textbox | C37: Hiển thị mã sản phẩm | D37: Status = enable Default = Lấy dữ liệu từ cột Mã sản phẩm trong bảng Sản phẩm Max-length = 50
A38: GUI-Detail-03 | B38: [Hãng] Textbox | C38: Hiển thị hãng | D38: Status = enable Default = Lấy dữ liệu từ cột Nhà cung cấp trong bảng Nhà cung cấp Max-length = 50
A39: GUI-Detail-04 | B39: [Màu] Textbox | C39: Hiển thị màu | D39: Status = enable Default = Lấy dữ liệu từ cột Màu trong bảng Sản phẩm Max-length = 15
A40: GUI-Detail-05 | B40: [Giá] Textbox | C40: Hiển thị giá | D40: Status = enable Default = Lấy dữ liệu từ cột Giá trong bảng Sản phẩm Max-length = 20
A41: GUI-Detail-06 | B41: [Tình trạng] Textbox | C41: Hiển thị tình trạng sản phẩm | D41: Status = enable Default = Lấy dữ liệu từ cột Tình trạng trong bảng Sản phẩm Max-length = 10
A42: GUI-Detail-07 | B42: [Chính sách bảo hành] Textbox | C42: Hiển thị chính sách bảo hành | D42: Status = enable Default = Lấy dữ liệu từ cột Chính sách bảo hành trong bảng Sản phẩm Max-length = 255
A43: GUI-Detail-08 | B43: [Ảnh sản phẩm] Image | C43: Hiển thị đúng ảnh đại diện sản phẩm | D43: Status = enable Default = Lấy dữ liệu từ cột Ảnh trong bảng Sản phẩm
A44: GUI-Detail-09 | B44: [Quay lại] Button | C44: Nhấn nút Quay lại | D44: Status = enable
B45: Function : Giỏ hàng
...

Sheet Layout Đặt hàng & QL đơn hàng

Sheet  Quản lý khách hàng - Admin
A2: Module Code | B2: Quản lý khách hàng
A3: Test requirement | B3: 1. Danh sách khách hàng 2. Lịch sử mua hàng khách hàng 3. Phân loại & CSKH
A4: Tester | B4: Hồ Bảo Toàn
A5: Pass | B5: Fail | C5: Untested | D5: N/A | E5: Number of Test cases
A6: =COUNTIF(F11:F1009,"Pass") -> 0 | B6: =COUNTIF(F11:F1009,"Fail") -> 0 | C6: =E6-D6-B6-A6 -> 30 | D6: =COUNTIF(F$11:F$1009,"N/A") -> 0 | E6: =COUNTA(A11:A1009) -> 30
A8: ID | B8: Test Case Description | C8: Test Case Procedure | D8: Expected Output | E8: Inter-test case Dependence | F8: Result | G8: Test date | H8: Note
B9: Function : Danh sách khách hàng
B10: Check FUNC-Danh sách khách hàng
A11: FUNC-Customer-01 | B11: Tìm kiếm khách hàng | C11: Nhập từ khoá và nhấn Tìm kiếm | D11: Hiển thị danh sách khách hàng phù hợp
A12: FUNC-Customer-02 | B12: Hiển thị danh sách khách hàng | C12: Truy cập màn hình quản lý khách hàng | D12: Hiển thị đầy đủ tên, SĐT, email, địa chỉ
A13: FUNC-Customer-03 | B13: Tra cứu lịch sử khách hàng | C13: Chọn khách hàng và nhấn "Tra cứu lịch sử" | D13: Hiển thị lịch sử giao dịch/chăm sóc khách
A14: FUNC-Customer-04 | B14: Phân loại và chăm sóc khách hàng | C14: Chọn khách hàng và nhấn "Phân loại & CSKH" | D14: Thực hiện chức năng phân loại/chăm sóc khách hàng
B18: Check GUI-Danh sách khách hàng
A19: GUI-Customer-01 | B19: [Tìm kiếm khách hàng] Textbox | C19: Nhập từ khoá tìm kiếm khách hàng | D19: Status = enable Max-length = 100
A20: GUI-Customer-02 | B20: [Tìm kiếm] Button | C20: Nhấn nút Tìm kiếm | D20: Status = enable
A21: GUI-Customer-03 | B21: [Danh sách khách hàng] Table | C21: Hiển thị họ tên, số điện thoại, email, địa chỉ từng khách | D21: Status = disable
A22: GUI-Customer-04 | B22: [Tra cứu lịch sử] Button | C22: Nhấn nút Tra cứu lịch sử | D22: Status = enable
A23: GUI-Customer-05 | B23: [Phân loại & CSKH] Button | C23: Nhấn nút Phân loại & CSKH | D23: Status = enable
B24: Function : Lịch sử mua hàng khách hàng
B25: Check FUNC-Lịch sử mua hàng khách hàng
A26: FUNC-CustomerHistory-01 | B26: Hiển thị lịch sử mua hàng | C26: Nhấn "Tra cứu lịch sử" của khách hàng bất kỳ | D26: Hiện popup hoặc giao diện hiển thị đúng danh sách hàng
A27: FUNC-CustomerHistory-02 | B27: Đóng/xem lại lịch sử mua hàng | C27: Nhấn nút Quay lại trên popup | D27: Popup bị đóng, trở về màn hình quản lý khách hàng
B28: Check GUI-Lịch sử mua hàng khách hàng
A29: GUI-CustomerHistory-01 | B29: [Tiêu đề popup] Label | C29: Hiển thị đúng tiêu đề “LỊCH SỬ MUA HÀNG KHÁCH A” | D29: Status = disable
A30: GUI-CustomerHistory-02 | B30: [Bảng lịch sử mua hàng] Table | C30: Hiển thị các cột: Sản phẩm, Thời gian, Số tiền | D30: Status = disable
A31: GUI-CustomerHistory-03 | B31: [Sản phẩm] Label | C31: Hiển thị tên sản phẩm đã mua | D31: Status = disable
A32: GUI-CustomerHistory-04 | B32: [Thời gian] Label | C32: Hiển thị đúng thời gian mua từng sản phẩm | D32: Status = disable
A33: GUI-CustomerHistory-05 | B33: [Số tiền] Label | C33: Hiển thị đúng số tiền từng sản phẩm/đơn mua | D33: Status = disable
A34: GUI-CustomerHistory-06 | B34: [Quay lại] Button | C34: Nhấn nút Quay lại trên popup lịch sử mua hàng | D34: Status = enable
B35: Function : Phân loại & CSKH
B36: Check FUNC-Phân loại & CSKH
A37: FUNC-Support-01 | B37: Hiển thị popup Phân loại & CSKH | C37: Chọn khách hàng và nhấn "Phân loại & CSKH" | D37: Hiển thị popup đúng dữ liệu khách hàng
A38: FUNC-Support-02 | B38: Chọn loại khách hàng | C38: Thay đổi dropdown loại khách hàng và lưu | D38: Dữ liệu loại KH được cập nhật đúng
A39: FUNC-Support-03 | B39: Nhập/đổi ghi chú, lựa chọn khuyến mãi/hậu mãi | C39: Nhập, tick chọn/bỏ chọn các mục, nhấn Lưu thay đổi | D39: Dữ liệu cập nhật đúng trong hệ thống
A40: FUNC-Support-04 | B40: Gửi khuyến mãi | C40: Tick các mục khuyến mãi và nhấn “Gửi khuyến mãi” | D40: Khuyến mãi được gửi cho khách hàng thành công
A41: FUNC-Support-05 | B41: Đóng popup/phân loại | C41: Nhấn nút đóng (nếu có) hoặc thao tác ngoài popup | D41: Popup đóng, quay lại màn hình quản lý khách hàng
B45: Check GUI-Phân loại & CSKH
A46: GUI-Support-01 | B46: [Tiêu đề popup] Label | C46: Hiển thị tiêu đề “PHÂN LOẠI & CSKH” | D46: Status = disable
A47: GUI-Support-02 | B47: [Khách hàng/SDT] Label | C47: Hiển thị chính xác tên khách hàng, SDT | D47: Status = disable
A48: GUI-Support-03 | B48: [Loại khách hàng] Dropdown | C48: Chọn loại khách hàng (Vip, Thường,...) | D48: Status = enable
...

Sheet Layout QL Khách Hàng - Admin 

Sheet Quản lý tài khoản
A2: Module Code | B2: Quản lý tài khoản
A3: Test requirement | B3: 1. Đăng nhập 2. Đăng kí 3. Thông tin cá nhân 4. Sửa thông tin cá nhân 5. Sửa mật khẩu
A4: Tester | B4: Hồ Bảo Toàn
A5: Pass | B5: Fail | C5: Untested | D5: N/A | E5: Number of Test cases
A6: =COUNTIF(F11:F1095,"Pass") -> 0 | B6: =COUNTIF(F11:F1095,"Fail") -> 0 | C6: =E6-D6-B6-A6 -> 66 | D6: =COUNTIF(F$11:F$1095,"N/A") -> 0 | E6: =COUNTA(A11:A1095) -> 66
A8: ID | B8: Test Case Description | C8: Test Case Procedure | D8: Expected Output | E8: Inter-test case Dependence | F8: Result | G8: Test date | H8: Note
B9: Function : Đăng nhập
B10: Check FUNC-Đăng nhập
A11: FUNC-Login-01 | B11: Đăng nhập thành công | C11: 1. Tại màn hình Đăng nhập. 2. Nhập Username hợp lệ (đã tồn tại). 3. Nhập Password hợp lệ (tương ứng với username). 4. Nhấn nút "Đăng nhập". | D11: Hiển thị thông báo: "Tài khoản hoặc mật khẩu không đúng".
A15: FUNC-Login-02 | B15: Đăng nhập thất bại (sai Password) | C15: 1. Tại màn hình Đăng nhập. 2. Nhập Username hợp lệ. 3. Nhập Password sai. 4. Nhấn nút "Đăng nhập". | D15: Hiển thị thông báo: "Tài khoản hoặc mật khẩu không đúng".
A16: FUNC-Login-03 | B16: Đăng nhập thất bại (sai Username) | C16: 1. Tại màn hình Đăng nhập. 2. Để trống trường Username. 3. Nhập Password bất kỳ. 4. Nhấn nút "Đăng nhập". | D16: Hiển thị thông báo: "Tài khoản hoặc mật khẩu không đúng".
A17: FUNC-Login-04 | B17: Đăng nhập thất bại (để trống Username) | C17: 1. Tại màn hình Đăng nhập. 2. Để trống trường Username. 3. Nhập Password bất kỳ. 4. Nhấn nút "Đăng nhập". | D17: Hiển thị thông báo: "Trường này là bắt buộc!" (thường hiển thị ngay tại ô Username).
A21: FUNC-Login-05 | B21: Đăng nhập thất bại (để trống Password) | C21: 1. Tại màn hình Đăng nhập. 2. Nhập Username hợp lệ. 3. Để trống trường Password. 4. Nhấn nút "Đăng nhập". 2. Để trống trường Username. 3. Nhập Password bất kỳ. 4. Nhấn nút "Đăng nhập". | D21: Hiển thị thông báo: "Trường này là bắt buộc!" (thường hiển thị ngay tại ô Password).
A25: FUNC-Login-06 | B25: Đăng nhập thất bại (để trống cả 2 trường) | C25: 1. Tại màn hình Đăng nhập. 2. Để trống trường Username. 3. Để trống trường Password. 4. Nhấn nút "Đăng nhập". . | D25: Hiển thị thông báo: "Trường này là bắt buộc!" (thường hiển thị ở cả 2 trường hoặc ít nhất là ở trường Username).
A29: FUNC-Login-07 | B29: Thao tác Hủy | C29: 1. Tại màn hình Đăng nhập. 2. Nhấn nút "Hủy". | D29: Đóng màn hình đăng nhập và quay trở về trang chủ.
B33: Check GUI-Đăng nhập
A34: GUI-Login-01 | B34: [Username] Textbox | C34: Nhập vào username | D34: Status = enable Default = Lấy dữ liệu từ cột Username trong bảng Tài khoản Max-length = 50
A35: GUI-Login-02 | B35: [Password] Textbox | C35: Nhập vào password | D35: Status = enable Default = Lấy dữ liệu từ cột Password trong bảng Tài khoản Max-length = 50
A36: GUI-Login-03 | B36: [Đăng nhập] Button | C36: Nhấn vào nút Đăng nhập | D36: Status = enable
A37: GUI-Login-04 | B37: [Hủy] Button | C37: Nhấn vào nút Hủy | D37: Status = enable
B38: Function : Đăng kí
B39: Check GUI-Đăng kí
A40: GUI-Reg-01 | B40: [Username] Textbox | C40: Nhập username hợp lệ | D40: Status = enable Default = Lấy dữ liệu từ cột Username trong bảng Tài khoản Max-length = 50
A43: GUI-Reg-02 | B43: [Password] Textbox | C43: Nhập password hợp lệ | D43: Status = enable
D44: Default = Lấy dữ liệu từ cột Password trong bảng Tài khoản
D45: Max-length = 50
A46: GUI-Reg-03 | B46: [Họ tên] Textbox | C46: Nhập họ tên hợp lệ | D46: Default = Lấy dữ liệu từ cột Tên khách hàng trong bảng Khách hàng Max-length= 50 Status = enable
A47: GUI-Reg-04 | B47: [Giới tính] Radio Button | C47: Chọn Nam hoặc Nữ | D47: Status = enable Default = Lấy dữ liệu từ cột Giới tính trong bảng Khách hàng
A48: GUI-Reg-05 | B48: [Email] Textbox | C48: Nhập email hợp lệ | D48: Status = enable Max-length= 50 Default = Lấy dữ liệu từ cột Email trong bảng Khách hàng
A49: GUI-Reg-06 | B49: [Số điện thoại] Textbox | C49: Nhập số điện thoại hợp lệ | D49: Status = enable Default = Lấy dữ liệu từ cột Số điện thoại trong bảng Khách hàng Max-length = 15
A50: GUI-Reg-07 | B50: [Địa chỉ] Textbox | C50: Nhập địa chỉ hợp lệ | D50: Status = enable Default = Lấy dữ liệu từ cột Địa chỉ trong bảng Khách hàng Max-length= 255
A51: GUI-Reg-08 | B51: [Đăng nhập] Button | C51: Nhấn nút Đăng nhập | D51: Status = enable Max-length= 15
A52: GUI-Reg-09 | B52: [Đăng ký] Button | C52: Nhấn nút Đăng ký khi hợp lệ | D52: Status = enable
B53: Check FUNC-Đăng kí
A54: FUNC-Reg-01 | B54: Đăng ký thành công | C54: 1. Tại màn hình Đăng ký. 2. Nhập Username hợp lệ (chưa tồn tại). 3. Nhập Password hợp lệ (vd: "Admin123"). 4. Nhập Họ tên. 5. Chọn Giới tính (vd: "Nam"). 6. Nhập Email hợp lệ (chưa tồn tại, vd: "test@gmail.com"). 7. Nhập Số điện thoại hợp lệ. 8. Nhập Địa chỉ. 9. Nhấn nút "Đăng ký". | D54: Chuyển: "vào màn hình chính của trang quản lý".
A55: FUNC-Reg-02 | B55: Đăng ký thất bại (Username đã tồn tại) | C55: 1. Để trống trường Username. 2. Nhập các thông tin còn lại. 3. Nhấn nút "Đăng ký". | D55: Hiển thị thông báo: "Trường này là bắt buộc!"
A56: FUNC-Reg-03 | B56: Đăng ký thất bại (Để trống Username) | C56: 1. Để trống trường Username. 2. Nhập các thông tin còn lại. 3. Nhấn nút "Đăng ký". | D56: Hiển thị thông báo: "Trường này là bắt buộc!"
A57: FUNC-Reg-04 | B57: Đăng ký thất bại (Để trống Password) | C57: 1. Để trống trường Password. 2. Nhập các thông tin còn lại. 3. Nhấn nút "Đăng ký". | D57: Hiển thị thông báo: "Trường này là bắt buộc!"
A58: FUNC-Reg-05 | B58: Đăng ký thất bại (Mật khẩu yếu) | C58: 1. Nhập Password không hợp lệ (vd: "123"). 2. Nhập các thông tin còn lại hợp lệ. 3. Nhấn nút "Đăng ký". | D58: Hiển thị thông báo: "Mật khẩu ít nhất 8 ký tự, bao gồm chữ hoa, chữ thường và số."
A59: FUNC-Reg-06 | B59: Đăng ký thất bại (Số điện thoại không hợp lệ) | C59: 1. Nhập Số điện thoại không hợp lệ (vd: "abc"). 2. Nhập các thông tin còn lại hợp lệ. 3. Nhấn nút "Đăng ký". | D59: Hiển thị thông báo: "Số điện thoại không hợp lệ."
...

Sheet Layout QL Tài khoản

Sheet Test Report
B1: TEST REPORT
B3: Project Name | C3: =[2]Cover!C4 -> Xây dựng hệ thống quản lý kho hàng và bán lẻ cho cửa hàng điện thoại | E3: Creator | H3: Hồ Bảo Toàn
B4: Project Code | C4: =[2]Cover!C5 -> KH52 | E4: Reviewer/Approver
B5: Document Code | C5: =C4&"_"&"Test Report"&"_"&"v1.0" -> KH52_Test Report_v1.0 | E5: Issue Date | H5: 42836
B6: Notes
B10: No | C10: Module code | D10: Pass | E10: Fail | F10: Untested | G10: N/A | H10: Number of test cases
B11: 1 | C11: Quản lý khách hàng - Admin | D11: =' Quản lý khách hàng - Admin'!A6 -> 0 | E11: =' Quản lý khách hàng - Admin'!B6 -> 0 | F11: =' Quản lý khách hàng - Admin'!C6 -> 30 | G11: =' Quản lý khách hàng - Admin'!D6 -> 0 | H11: =' Quản lý khách hàng - Admin'!E6 -> 30
B12: 1 | C12: Quản lý tài khoản | D12: ='Quản lý tài khoản'!A6 -> 0 | E12: ='Quản lý tài khoản'!B6 -> 0 | F12: ='Quản lý tài khoản'!C6 -> 66 | G12: ='Quản lý tài khoản'!D6 -> 0 | H12: ='Quản lý tài khoản'!E6 -> 66
B13: 3 | C13: Đặt hàng & Quản lý đơn hàng | D13: ='Đặt hàng & quản lý đơn hàng'!A6 -> 0 | E13: ='Đặt hàng & quản lý đơn hàng'!B6 -> 0 | F13: ='Đặt hàng & quản lý đơn hàng'!C6 -> 85 | G13: ='Đặt hàng & quản lý đơn hàng'!D6 -> 0 | H13: ='Đặt hàng & quản lý đơn hàng'!E6 -> 85
B14: 4 | C14: Quản lý chi phí vận hành | D14: =QLChiPhiVanHanh!A6 -> 0 | E14: =QLChiPhiVanHanh!B6 -> 0 | F14: =QLChiPhiVanHanh!C6 -> 58 | G14: =QLChiPhiVanHanh!D6 -> 0 | H14: =QLChiPhiVanHanh!E6 -> 58
B15: 5 | C15: Tìm kiếm sản phẩm | D15: ='Tìm kiếm sản phẩm'!A6 -> 0 | E15: ='Tìm kiếm sản phẩm'!B6 -> 0 | F15: ='Tìm kiếm sản phẩm'!C6 -> 14 | G15: ='Tìm kiếm sản phẩm'!D6 -> 0 | H15: ='Tìm kiếm sản phẩm'!E6 -> 14
C16: Sub total | D16: =SUM(D15:D15) -> 0 | E16: =SUM(E15:E15) -> 0 | F16: =SUM(F11:F15) -> 253 | G16: =SUM(G15:G15) -> 0 | H16: =SUM(H11:H15) -> 253
C18: Test coverage | E18: =(D16+E16)*100/(H16-G16) -> 0 | F18: %
C19: Test successful coverage | E19: =D16*100/(H16-G16) -> 0 | F19: %
